Workbook

Sheet 통계
B2: 영역 | C2: 분야 | E2: 항목수 | F2: 운영여부
F3: Y | G3: N | H3: N/A
B4: 1.관리체계 수립 및 운영 | C4: 1.1. | D4: 관리체계 기반 마련 | E4: =SUM(F4:H4) -> 6 | F4: =COUNTIF('ISMS-P'!G6:$G$11,"Y") -> 6 | G4: =COUNTIF('ISMS-P'!$G6:H$11,"N") -> 0 | H4: =COUNTIF('ISMS-P'!$G6:I$11,"N/A") -> 0
C5: 1.2. | D5: 위험 관리 | E5: =SUM(F5:H5) -> 4 | F5: =COUNTIF('ISMS-P'!$G$12:$G$15,"Y") -> 4 | G5: =COUNTIF('ISMS-P'!$G$12:$G$15,"N") -> 0 | H5: =COUNTIF('ISMS-P'!$G$12:$G$15,"N/A") -> 0
C6: 1.3. | D6: 관리체계 운영 | E6: =SUM(F6:H6) -> 3 | F6: =COUNTIF('ISMS-P'!$G$16:$G$18,"Y") -> 3 | G6: =COUNTIF('ISMS-P'!$G$16:$G$18,"N") -> 0 | H6: =COUNTIF('ISMS-P'!$G$16:$G$18,"N/A") -> 0
C7: 1.4. | D7: 관리체계 점검 및 개선 | E7: =SUM(F7:H7) -> 3 | F7: =COUNTIF('ISMS-P'!$G$19:$G$21,"Y") -> 3 | G7: =COUNTIF('ISMS-P'!$G$19:$G$21,"N") -> 0 | H7: =COUNTIF('ISMS-P'!$G$19:$G$21,"N/A") -> 0
C8: 소계 | E8: =SUM(E4:E7) -> 16 | F8: =SUM(F4:F7) -> 16 | G8: =SUM(G4:G7) -> 0 | H8: =SUM(H4:H7) -> 0
B9: 2. 보호대책 요구사항 | C9: 2.1. | D9: 정책, 조직, 자산 관리 | E9: =SUM(F9:H9) -> 3 | F9: =COUNTIF('ISMS-P'!$G$23:$G$25,"Y") -> 3 | G9: =COUNTIF('ISMS-P'!$G$23:$G$25,"N") -> 0 | H9: =COUNTIF('ISMS-P'!$G$23:$G$25,"N/A") -> 0
C10: 2.2. | D10: 인적 보안 | E10: =SUM(F10:H10) -> 6 | F10: =COUNTIF('ISMS-P'!$G$26:$G$31,"Y") -> 6 | G10: =COUNTIF('ISMS-P'!$G$26:$G$31,"N") -> 0 | H10: =COUNTIF('ISMS-P'!$G$26:$G$31,"N/A") -> 0
C11: 2.3. | D11: 외부자 보안 | E11: =SUM(F11:H11) -> 4 | F11: =COUNTIF('ISMS-P'!$G$32:$G$35,"Y") -> 4 | G11: =COUNTIF('ISMS-P'!$G$32:$G$35,"N") -> 0 | H11: =COUNTIF('ISMS-P'!$G$32:$G$35,"N/A") -> 0
C12: 2.4. | D12: 물리 보안 | E12: =SUM(F12:H12) -> 7 | F12: =COUNTIF('ISMS-P'!$G$36:$G$42,"Y") -> 7 | G12: =COUNTIF('ISMS-P'!$G$36:$G$42,"N") -> 0 | H12: =COUNTIF('ISMS-P'!$G$36:$G$42,"N/A") -> 0
C13: 2.5. | D13: 인증 및 권한관리 | E13: =SUM(F13:H13) -> 6 | F13: =COUNTIF('ISMS-P'!$G$43:$G$48,"Y") -> 6 | G13: =COUNTIF('ISMS-P'!$G$43:$G$48,"N") -> 0 | H13: =COUNTIF('ISMS-P'!$G$43:$G$48,"N/A") -> 0
C14: 2.6. | D14: 접근통제 | E14: =SUM(F14:H14) -> 7 | F14: =COUNTIF('ISMS-P'!$G$49:$G$55,"Y") -> 7 | G14: =COUNTIF('ISMS-P'!$G$49:$G$55,"N") -> 0 | H14: =COUNTIF('ISMS-P'!$G$49:$G$55,"N/A") -> 0
C15: 2.7. | D15: 암호화 적용 | E15: =SUM(F15:H15) -> 2 | F15: =COUNTIF('ISMS-P'!$G$56:$G$57,"Y") -> 2 | G15: =COUNTIF('ISMS-P'!$G$56:$G$57,"N") -> 0 | H15: =COUNTIF('ISMS-P'!$G$56:$G$57,"N/A") -> 0
C16: 2.8. | D16: 정보시스템 도입 및 개발 보안 | E16: =SUM(F16:H16) -> 6 | F16: =COUNTIF('ISMS-P'!$G$58:$G$63,F3) -> 6 | G16: =COUNTIF('ISMS-P'!$G$58:$G$63,G3) -> 0 | H16: =COUNTIF('ISMS-P'!$G$58:$G$63,H3) -> 0
C17: 2.9. | D17: 시스템 및 서비스 운영관리 | E17: =SUM(F17:H17) -> 7 | F17: =COUNTIF('ISMS-P'!$G$64:$G$70,F3) -> 7 | G17: =COUNTIF('ISMS-P'!$G$64:$G$70,G3) -> 0 | H17: =COUNTIF('ISMS-P'!$G$64:$G$70,H3) -> 0
C18: 2.10. | D18: 시스템 및 서비스 보안관리 | E18: =SUM(F18:H18) -> 9 | F18: =COUNTIF('ISMS-P'!$G$71:$G$79,F3) -> 8 | G18: =COUNTIF('ISMS-P'!$G$71:$G$79,G3) -> 0 | H18: =COUNTIF('ISMS-P'!$G$71:$G$79,H3) -> 1
C19: 2.11. | D19: 사고 예방 및 대응 | E19: =SUM(F19:H19) -> 5 | F19: =COUNTIF('ISMS-P'!$G$80:$G$84,F3) -> 5 | G19: =COUNTIF('ISMS-P'!$G$80:$G$84,G3) -> 0 | H19: =COUNTIF('ISMS-P'!$G$80:$G$84,H3) -> 0
C20: 2.12. | D20: 재해복구 | E20: =SUM(F20:H20) -> 2 | F20: =COUNTIF('ISMS-P'!$G$85:$G$86,F3) -> 2 | G20: =COUNTIF('ISMS-P'!$G$85:$G$86,G3) -> 0 | H20: =COUNTIF('ISMS-P'!$G$85:$G$86,H3) -> 0
C21: 소계 | E21: =SUM(E9:E20) -> 64 | F21: =SUM(F9:F20) -> 63 | G21: =SUM(G9:G20) -> 0 | H21: =SUM(H9:H20) -> 1
B22: 3. 개인정보 처리단계별 요구사항 | C22: 3.1. | D22: 개인정보 수집 시 보호조치 | E22: =SUM(F22:H22) -> 7 | F22: =COUNTIF('ISMS-P'!$G$88:$G$94,"Y") -> 5 | G22: =COUNTIF('ISMS-P'!$G$88:$G$94,"N") -> 0 | H22: =COUNTIF('ISMS-P'!$G$88:$G$94,"N/A") -> 2
C23: 3.2. | D23: 개인정보 보유 및 이용 시 보호조치 | E23: =SUM(F23:H23) -> 5 | F23: =COUNTIF('ISMS-P'!$G$95:$G$99,"Y") -> 2 | G23: =COUNTIF('ISMS-P'!$G$95:$G$99,"N") -> 0 | H23: =COUNTIF('ISMS-P'!$G$95:$G$99,"N/A") -> 3
C24: 3.3. | D24: 개인정보 제공 시 보호조치 | E24: =SUM(F24:H24) -> 4 | F24: =COUNTIF('ISMS-P'!$G$100:$G$103,"Y") -> 1 | G24: =COUNTIF('ISMS-P'!$G$100:$G$103,"N") -> 0 | H24: =COUNTIF('ISMS-P'!$G$100:$G$103,"N/A") -> 3
C25: 3.4. | D25: 개인정보 파기 시 보호조치 | E25: =SUM(F25:H25) -> 2 | F25: =COUNTIF('[1]ISMS-P'!$G$104:$G$105,F3) -> 2 | G25: =COUNTIF('[1]ISMS-P'!$G$104:$G$105,G3) -> 0 | H25: =COUNTIF('[1]ISMS-P'!$G$104:$G$105,H3) -> 0
C26: 3.5. | D26: 정보주체 권리보호 | E26: =SUM(F26:H26) -> 3 | F26: =COUNTIF('[1]ISMS-P'!$G$106:$G$108,F3) -> 2 | G26: =COUNTIF('[1]ISMS-P'!$G$106:$G$108,G3) -> 0 | H26: =COUNTIF('[1]ISMS-P'!$G$106:$G$108,H3) -> 1
C27: 소계 | E27: =SUM(E22:E26) -> 21 | F27: =SUM(F22:F26) -> 12 | G27: =SUM(G22:G26) -> 0 | H27: =SUM(H22:H26) -> 9
B28: 총계 | E28: =E8+E21+E27 -> 101 | F28: =F8+F21+F27 -> 91 | G28: =G8+G21+G27 -> 0 | H28: =H8+H21+H27 -> 10

Sheet ISMS-P
B2: ISMS-P 운영명세서(기업명 : 신한DS)
B4: 분야 | D4: 항목 | F4: 상세내용 | G4: ①운영여부 | H4: ②인증 구분 | I4: ③운영현황 (또는 미선택사유) | J4: ④관련문서 (정책, 지침 등 세부조항번호까지) | K4: ⑤기록 (증적자료)
B5: 가. 관리체계 수립 및 운영
B6: 1.1. | C6: 관리체계 기반 마련 | D6: 1.1.1 | E6: 경영진의 참여 | F6: 최고경영자는 정보보호 및 개인정보보호 관리체계의 수립과 운영활동 전반에 경영진의 참여가 이루어질 수 있도록 보고 및 의사결정 체계를 수립하여 운영하여야 한다. | G6: Y | H6: ISMS-P | I6: ▶최고책임자는 회사의 정보보호 및 개인정보보호가 이루어질 수 있도록 정보보호 조직(부서)을 구성하고 있으며, 정보보호 관리체계를 구축하기 위한 정보보호관리규정의 제·개정 사항을 승인하고 있음 ※ 아래의 사항에 대해서 최고책임자에게 보고하고 있음 - 정보보호위원회 결과(정보기술 부문 계획, 정보보호 정책 개정, 연간 정보보호 운영 계획 등) - 정보보호 운영 활동(정보보호의 날, 개인정보/퇴사자 모니터링 등) | J6: 「정보보안관리지침」 제4조(정보보호 주관부서 구성) ①항 제12조(정보보호위원회) ⑤항 제13조(정보보호 정책 수립) ④항 제17조(정보기술부문 계획 보고) ②항 제18조(정보보호의 날 운영) ②항 | K6: - 정보보호 조직도(전사 포함) - 정보보보위원회 결과 보고 - 정보보호 규정/지침 개정 품의 - 정보보호 절차서 개정 품의 - 월간보안활동 보고
D7: 1.1.2 | E7: 최고책임자의 지정 | F7: 최고경영자는 정보보호 업무를 총괄하는 정보보호 최고책임자와 개인정보보호 업무를 총괄하는 개인정보보호 책임자를 예산·인력 등 자원을 할당할 수 있는 임원급으로 지정하여야 한다. | G7: Y | H7: ISMS-P | I7: 정보보호최고책임자/개인정보보호책임자는 정보보호 주관본부의 본부장으로 임명하고 있으며, 최고경영자의 권한을 일부 위임받아 정보보호를 위한 예산과 인력을 승인할 수 있음 ※ 정보보호최고책임자와 개인정보보호책임자는 정보보호본부 본부장이 겸직하고 있음 | J7: 「정보보안관리지침」 제6조(정보보호최고책임자) ①항, ④항 「개인정보보호관리지침」 제4조(개인정보보호책임자) ①항 | K7: - 직제규정 - 임원 및 본부장 업무분장 안내 - CISO_지정승인
D8: 1.1.3 | E8: 조직 구성 | F8: 최고경영자는 정보보호와 개인정보보호의 효과적 구현을 위한 실무조직, 조직 전반의 정보보호와 개인정보보호 관련 주요 사항을 검토 및 의결할 수 있는 위원회, 전사적 보호활동을 위한 부서별 정보보호와 개인정보보호 담당자로 구성된 협의체를 구성하여 운영하여야 한다. | G8: Y | H8: ISMS-P | I8: 정보보호 및 개인정보보호의 실무적인 사항을 조정하기 위해 정보보호실무협의회((개인)정보보호담당자로 구성)를 구성/운영하며, 정보보호위원회((개인)정보보호관리자로 구성)를 통해 정보보호에 관한사항을 심의·의결·보고 하고 있음 - 각 부서별 (개인)정보보호관리자 및 담당자를 지정하여 정보보호 관리체계를 운영하고 있음 | J8: 「정보보안관리지침」 제7조(정보보호관리자) 제8조(정보보호담당자) 제9조(부서정보보호관리자) 제10조(부서정보보호담당자) 제11조(정보보호실무협의회) ①항, ②항 제12조(정보보호위원회) ①항,②항 「개인정보보호관리지침」 제5조(개인정보보호관리자) 제6조(개인정보보호담당자) 제7조(개인정보 취급부서장) 제8조(개인정보보호 조직) | K8: - 정보보호위원회 결과 보고 - 정보보호실무협의회
D9: 1.1.4 | E9: 범위 설정 | F9: 조직의 핵심 서비스와 개인정보 처리 현황 등을 고려하여 관리체계 범위를 설정하고, 관련된 서비스를 비롯하여 개인정보 처리 업무와 조직, 자산, 물리적 위치 등을 문서화하여야 한다. | G9: Y | H9: ISMS-P | I9: 조직의 (개인)정보보호 관리체계의 범위를 설정하고, 관련된 서비스의 현황을 문서화하여 관리하고 있음 - 각 부서는 보유하고 있는 정보자산 목록을 작성/관리하고, 정보보호담당자는 자산관리대장에 대한 관리 및 통제를 실시하고 있음 | J9: 「정보보안관리지침」 제8조(정보보호담당자) ②항 3호 제10조(부서정보보호담당자) ③항 1호 「개인정보보호관리지침」 제7조(개인정보 처리부서장) ①항 | K9: - 정보자산목록 - 개인정보 흐름표 - ISMS-P 인증 범위 소개자료 > 개인정보 흐름도 포함 > 서비스 흐름도 포함 > 네트워크 구성도 포함 > 정보보호 조직도(전사 포함)
D10: 1.1.5 | E10: 정책 수립 | F10: 정보보호와 개인정보보호 정책 및 시행문서를 수립·작성하며, 이때 조직의 정보보호와 개인정보보호 방침 및 방향을 명확하게 제시하여야 한다. 또한 정책과 시행문서는 경영진 승인을 받고, 임직원 및 관련자에게 이해하기 쉬운 형태로 전달하여야 한다. | G10: Y | H10: ISMS-P | I10: (개인)정보보호 정책을 제·개정 시 정보보호위원회를 통해 변경 사항을 심의·의결하고 있으며, 최고경영자 및 정보보호최고책임자 승인 후에 임직원 및 관련자에게 공표하고 있음 - 골드윙(사내포탈) 내 규정/법률에 개정된 정책을 게시 - 전사공지를 통해 변경된 정보보호 정책을 공지하고 있음 | J10: 「정보보안관리지침」 제13조(정보보호 정책 수립) 제14조(정보보호 정책 공표) 제15조(정보보호 정책 검토) 「개인정보보호관리지침」 제11조(개인정보보호 정책 수립 및 운영) | K10: - 정보보호위원회 - 전사공지(골드윙) - 정보보호 규정/지침 개정 품의
D11: 1.1.6 | E11: 자원 할당 | F11: 최고경영자는 정보보호와 개인정보보호 분야별 전문성을 갖춘 인력을 확보하고, 관리체계의 효과적 구현과 지속적 운영을 위한 예산 및 자원을 할당하여야 한다. | G11: Y | H11: ISMS-P | I11: 최고책임자는 정보보호 조직(부서)을 구성하며, 정보기술부문 및 정보보호 운영 계획을 승인함으로 정보보호 관리체계가 구축/운영될 수 있도록 관리함 - 정보보호호위원회에서 연간 정보기술부문 계획 및 전년도 결과를 심의·의결 하고 있음(정보보호위원회) - 정보보호위원회 결과를 최고경영자에게 보고하고 있음 - '23년 1월 기준 정보기술부문의 20.0%를 정보보호 예산으로 배정 - '23년 1월 기준 정보기술부문의 18.0%(11명)를 정보보호 인력으로 구성 | J11: 「정보보안관리지침」 제4조(정보보호 주관부서 구성) 제5조(정보보호 주관부서 운영) ④항 제6조(정보보호최고책임자) ④항 제16조(정보기술부문 계획 수립) ③항 | K11: - 정보보호위원회 결과 보고
B12: 1.2. | C12: 위험 관리 | D12: 1.2.1 | E12: 정보자산 식별 | F12: 조직의 업무특성에 따라 정보자산 분류기준을 수립하여 관리체계 범위 내 모든 정보자산을 식별·분류하고, 중요도를 산정한 후 그 목록을 최신으로 관리하여야 한다. | G12: Y | H12: ISMS-P | I12: 정보시스템(서버, WEB/WAS, DBMS, 네트워크, 보안장비 등)을 목록화하여 관리하고 있으며, 기밀성/무결성/가용성을 기준으로 중요도를 산정하여 관리하고 있음 - 정보시스템 변경 시 운영 담당자로부터 업데이트 된 현황을 받아, 목록을 업데이트 하고 있음 | J12: 「정보보안관리지침」 제10조(부서정보보호담당자) ③항 제38조(정보시스템 식별 및 관리) ①항, ②항, ③항, ④항, ⑥항 | K12: - 정보자산목록
D13: 1.2.2 | E13: 현황 및 흐름분석 | F13: 관리체계 전 영역에 대한 정보서비스 및 개인정보 처리 현황을 분석하고 업무 절차와 흐름을 파악하여 문서화하며, 이를 주기적으로 검토하여 최신성을 유지하여야 한다. | G13: Y | H13: ISMS-P | I13: 정보서비스 및 개인정보처리 흐름도를 식별하고 있으며, 주기적으로 검토하여 문서를 현행화 하고 있음 - 정보서비스 흐름도, 개인정보 흐름표, 개인정보 흐름도를 작성하여 관리하고 있음 | J13: 「정보보안관리지침」 제38조(정보시스템 식별 및 관리) ①항, ②항, ③항, ④항, ⑥항 「개인정보보호관리지침」 제45조(개인정보 흐름 분석) ①항, ②항 | K13: - 개인정보 흐름도/흐름표
D14: 1.2.3 | E14: 위험 평가 | F14: 조직의 대내외 환경분석을 통해 유형별 위협정보를 수집하고 조직에 적합한 위험 평가 방법을 선정하여 관리체계 전 영역에 대하여 연 1회 이상 위험을 평가하며, 수용할 수 있는 위험은 경영진의 승인을 받아 관리하여야 한다. | G14: Y | H14: ISMS-P | I14: 매년 보안 취약점 진단 및 위험평가를 통하여, 위험을 식별하고 보호대책을 수립하고 있음. 위험평가 결과는 정보보호 최고책임자에게 보고하고 있음 - '23년 06~08월 취약점 진단 사업을 통하여 취약점 진단 및 위험평가를 수행하였음 - '23년 11월 전수조치 후 이행점검을 수행함 ※ ISO27001 인증을 유지하고 있으며, '23년도 하반기 위험평가 진행 | J14: 「정보보안관리지침」 제41조(위험관리 계획 수립) 제42조(위험평가) 제43조(보호대책 수립) | K14: - 취약점 진단 결과 - 위험평가 보고서 - 위험관리절차서 - 취약점점검절차서 - 개인정보 흐름도/흐름표
D15: 1.2.4 | E15: 보호대책 선정 | F15: 위험 평가 결과에 따라 식별된 위험을 처리하기 위하여 조직에 적합한 보호대책을 선정하고, 보호대책의 우선순위와 일정·담당자·예산 등을 포함한 이행계획을 수립하여 경영진의 승인을 받아야 한다. | G15: Y | H15: ISMS-P | I15: 식별된 위험은 위험도를 산정(자산가치,위협,취약성)하여 보호대책을 수립하며, 관리 및 이행점검을 실시하고 있음 - 보호대책(조치계획)은 조치 일정/담당부서를 명시하여 관리하고 있음 - 보호대책은 정보보호 최고책임자에게 보고하고 있음 | J15: 「정보보안관리지침」 제41조(위험관리 계획 수립) 제42조(위험평가) 제43조(보호대책 수립) | K15: - 취약점 진단 결과 - 위험평가 보고서 - 위험관리절차서 - 취약점진단절차서 - 월간보안활동 보고
B16: 1.3. | C16: 관리체계 운영 | D16: 1.3.1 | E16: 보호대책 구현 | F16: 선정한 보호대책은 이행계획에 따라 효과적으로 구현하고, 경영진은 이행결과의 정확성과 효과성 여부를 확인하여야 한다. | G16: Y | H16: ISMS-P | I16: 위험평가를 통해 보호대책을 수립하였으며, 해당 내역(위험평가, 조치내역)을 경영진에 보고하고 있음 | J16: 「정보보안관리지침」 제41조(위험관리 계획 수립) 제42조(위험평가) 제43조(보호대책 수립) | K16: - 취약점 진단 결과 - 위험평가 보고서 - 정보보보위원회 결과 보고
D17: 1.3.2 | E17: 보호대책 공유 | F17: 보호대책의 실제 운영 또는 시행할 부서 및 담당자를 파악하여 관련 내용을 공유하고 교육하여 지속적으로 운영되도록 하여야 한다. | G17: Y | H17: ISMS-P | I17: 취약점 진단/위험평가 결과를 개발/운영/보안 담당자가 참석하여 취약점 현황 및 조치 관련 사항을 공유하고 있음 | J17: 「정보보안관리지침」 제43조(보호대책 수립) 제25조(정보보호 교육 수행) | K17: - 취약점 진단 결과 및 조치 사항 공유 - 정보보보위원회 결과 보고
D18: 1.3.3 | E18: 운영현황 관리 | F18: 조직이 수립한 관리체계에 따라 상시적 또는 주기적으로 수행하여야 하는 운영활동 및 수행 내역은 식별 및 추적이 가능하도록 기록하여 관리하고, 경영진은 주기적으로 운영활동의 효과성을 확인하여 관리하여야 한다. | G18: Y | H18: ISMS-P | I18: 매년 정보보호위원회를 개최하여 정보보호 운영 계획 등에 대해 심의/의결/보고 하고 있으며, 매월 보안점검을 실시하여 경영진에 보고하고 있음 - 개인/정보보호 모니터링(정보보호의날, 퇴사자/개인정보 모니터링), 개인/정보보호 인증 대응, 개인/정보보안 교육 등에 관한 사항을 계획/보고하고 있음 | J18: 「정보보안관리지침」 제12조(정보보호위원회) ①항, ⑤항 제18조(정보보호의 날 운영) | K18: - 정보보호위원회 - 월간보안활동 보고
B19: 1.4. | C19: 관리체계 점검 및 개선 | D19: 1.4.1 | E19: 법적 요구사항 준수 검토 | F19: 조직이 준수하여야 할 정보보호 및 개인정보보호 관련 법적 요구사항을 주기적으로 파악하여 규정에 반영하고, 준수 여부를 지속적으로 검토하여야 한다. | G19: Y | H19: ISMS-P | I19: 정보보호 및 개인정보보호 관련 법적 요구사항에 대하여 매년 그룹 정보보안 컴플라이언스 점검(신한 지주 주관)을 받고 있음 - 년간 수시감사(컴플라이언스팀) 계획을 수립하여 이행하고 있음 정보보호 및 개인정보보호 규정/지침 개정시 법적 요구사항을 반영하여 법률검토(컴플라이언스팀)를 진행하고 있음 | J19: 「정보보안관리지침」 제121조(정보보호 감사) | K19: - 감사결과 - 규정/지침 개정 품의
D20: 1.4.2 | E20: 관리체계 점검 | F20: 관리체계가 내부 정책 및 법적 요구사항에 따라 효과적으로 운영되고 있는지 독립성과 전문성이 확보된 인력을 구성하여 연 1회 이상 점검하고, 발견된 문제점을 경영진에게 보고하여야 한다. | G20: Y | H20: ISMS-P | I20: 감사는 기능별로 재무감사, 준법감사, IT감사로 구분하고 있으며, 준법감사는 관련법령, 규정 등을 준수하고 있는지 상시적으로 감시하고 있음 - 감사는 컴플라이언스팀에서 수행하고 있으며, 사무분장규정/감사직무규정을 통해 권한과 의무를 명시하고 있음 - 감사 결과(수시 등)에 대해서는 경영진에게 보고하고 있음 | J20: 「감사직무규정」 제4조(권한과 의무) 제5조(감사의 구분) 제15조(감사인의 의무) 제16조(감사인의 권한) 「사무분장규정」 제8조(컴플라이언스 Cell) | K20: - 감사결과 - 감사보고서
D21: 1.4.3 | E21: 관리체계 개선 | F21: 법적 요구사항 준수검토 및 관리체계 점검을 통해 식별된 관리체계상의 문제점에 대한 원인을 분석하고 재발방지 대책을 수립·이행하여야 하며, 경영진은 개선 결과의 정확성과 효과성 여부를 확인하여야 한다. | G21: Y | H21: ISMS-P | I21: 수시 감사 결과 개선조치사항에 대해서 이행여부를 경영진에게 보고하고 관리하고 있음 - 수시감사 결과 시 발견된 개선조치 사항에 대해 조치계획/조치부서/조치기한을 수립하여 관리하고 있음 (매월 수시감사 실시) | J21: 「감사직무규정」 제4조(권한과 의무) 제5조(감사의 구분) 제15조(감사인의 의무) 제16조(감사인의 권한) | K21: - 감사 조치요구사항 - 감사 조치요구사항 정리보고서
B22: 나. 보호대책 요구사항
B23: 2.1. | C23: 정책, 조직, 자산 관리 | D23: 2.1.1 | E23: 정책의 유지관리 | F23: 정보보호 및 개인정보보호 관련 정책과 시행문서는 법령 및 규제, 상위 조직 및 관련 기관 정책과의 연계성, 조직의 대내외 환경변화 등에 따라 주기적으로 검토하여 필요한 경우 제∙개정하고 그 내역을 이력관리하여야 한다. | G23: Y | H23: ISMS-P | I23: ▶정보보호 관리체게의 적절성 및 준법성을 보장하기 위해 연 1회 이상 법률 제•개정 내용을 반영하고, 준법담당부서에 법률검토를 의뢰하여 법적 요구사항 준수여부를 검토 받고 있음 - 정보보호규정 및 지침 제정 시 관련 현업부서의 담당자의 검토 의견(정보보호위원회 등)을 수렴하여 조직 내에서 실제 수행하는 정보보호 활동 내용이 반영될 수 있도록 함 - 정보보호규정 및 관련 지침의 이력관리 및 이행에 관련된 문서는 제·개정, 배포 및 폐기 등에 관하여 관련 규정을 준수하여 운영하고 있음 | J23: 「정보보안관리지침」 제13조(정보보호 정책 수립) ①항, ②항 제15조(정보보호 정책 검토) ①항, ②항 | K23: - 정보보호 규정/지침 개정 품의 (법률검토 포함) - 정보보보위원회 결과 보고
D24: 2.1.2 | E24: 조직의 유지관리 | F24: 조직의 각 구성원에게 정보보호와 개인정보보호 관련 역할 및 책임을 할당하고, 그 활동을 평가할 수 있는 체계와 조직 및 조직의 구성원 간 상호 의사소통할 수 있는 체계를 수립하여 운영하여야 한다. | G24: Y | H24: ISMS-P | I24: 개인/정보보호 조직은 업무 R&R을 통해 상호 협력하여 정보보호 업무를 수행하고 있음 - 정보보호책임자 및 관련 담당자의 역할 및 책임을 직무기술서에 기술함 - KPI 항목에 평가 항목을 추가하여 정보보호 관련 담당자에 대한 정보보호 활동에 대한 평가를 수행하고 있음 | J24: 「정보보안관리지침」 제4조(정보보호 주관부서 구성) 제5조(정보보호 주관부서 운영) 제6조(정보보호최고책임자) 제7조(정보보호관리자) 제8조(정보보호담당자) | K24: - 사무분장규정 - 조직의 유지관리 - 부서별 정보보호 담당자 현황 - (사내보안)업무분장현황
D25: 2.1.3 | E25: 정보자산 관리 | F25: 정보자산의 용도와 중요도에 따른 취급 절차 및 보호대책을 수립·이행하고, 자산별 책임소재를 명확히 정의하여 관리하여야 한다. | G25: Y | H25: ISMS-P | I25: 식별된 정보자산에 대한 정보자산명, 용도, 책임자 및 관리자, 관리부서 등 정보자산의 정보를 확인할 수 있도록 목록으로 관리함 - 정보자산관리지침에 자산중요도를 평가하도록 명시 되어 있고, 시행하고 있음 - 정보자산은 분기별로 최신화하여 관리하고 있음 | J25: 「정보보안관리지침」 제38조(정보시스템 식별 및 관리) ①항, ②항, ③항, ⑥항 | K25: - 정보자산목록
B26: 2.2. | C26: 인적 보안 | D26: 2.2.1 | E26: 주요 직무자 지정 및 관리 | F26: 개인정보 및 중요정보의 취급이나 주요 시스템 접근 등 주요 직무의 기준과 관리방안을 수립하고, 주요 직무자를 최소한으로 지정하여 그 목록을 최신으로 관리하여야 한다. | G26: Y | H26: ISMS-P | I26: 회사 내 중요 정보자산을 취급하는 직무를 분류하여 관리하도록 지침에 명시되어 있으며, 중요시스템을 지정하여 목록화하고 있음 - 중요정보 취급자는 최소한으로 지정하고 있으며, 매월 직무자 현황을 검토하고 있음 - 개인정보취급자를 지정하고 매월 보안 점검(모니터링 보고) 시 목록을 최신화 하고 있음 | J26: 「정보보안관리지침」 제20조(주요 직무 분리) 「개인정보보호관리지침」 제30조(개인정보취급자에 대한 감독) | K26: - 월간보안활동 보고 *주요 단말 관리자, 개인정보 취급자 등
D27: 2.2.2 | E27: 직무 분리 | F27: 권한 오·남용 등으로 인한 잠재적인 피해 예방을 위하여 직무 분리 기준을 수립하고 적용하여야 한다. 다만 불가피하게 직무 분리가 어려운 경우 별도의 보완대책을 마련하여 이행하여야 한다. | G27: Y | H27: ISMS-P | I27: 각 업무별 직무기술서를 정의하고, 관련 지침 등에 역할 및 업무처리절차 등을 명시하고 있음 - 보안은 보안컨설팅팀에서 수행하고 있음 - 서비스별 담당자를 분리하여 운영하고 있으며, 개발/운영 시스템 분리운영 및 보안대책(사용자 접근통제-계정관리솔루션-형상관리 상호견제체계 등)을 수립하여 운영하고 있음 | J27: 「정보보안관리지침」 제20조(주요 직무 분리) 「개인정보보호관리지침」 제30조(개인정보취급자에 대한 감독) | K27: - 팀 정의서 - 사무분장규정
D28: 2.2.3 | E28: 보안 서약 | F28: 정보자산을 취급하거나 접근권한이 부여된 임직원·임시직원·외부자 등이 내부 정책 및 관련 법규, 비밀유지 의무 등 준수사항을 명확히 인지할 수 있도록 업무 특성에 따른 정보보호 서약을 받아야 한다. | G28: Y | H28: ISMS-P | I28: 임직원에 대해 정보보호서약서 등을 징구하여 관리하고 있음 - 입사 시 보안서약서 및 개인정보 비밀유지 서약서, 연 1회 NEXT(e-HR)를 통해 보안서약서 징구함 - 수행 인력 투입/철수 시 각 인력에 대하여 정보보호서약서를 작성받음 - 퇴직 시에도 정보보호서약서를 징구함 - 정보보호서약서 및 비밀유지서약서는 물리적으로 안전한 장소에 보관하고 있음(인사팀에서 시건장치가 있는 부서전용 캐비닛에 보관 중임) | J28: 「정보보안관리지침」 제21조(외주인력 관리방안) ①항, ②항, ③항 제22조(보안서약서 징구) 제89조(외주개발 계약) 「개인정보보호관리지침」 제31조(비밀유지) | K28: - 보안서약서 양식 및 샘플(임직원, 외주직원) - NEXT 서약서 징구(보안서약서)
D29: 2.2.4 | E29: 인식제고 및 교육훈련 | F29: 임직원 및 관련 외부자가 조직의 관리체계와 정책을 이해하고 직무별 전문성을 확보할 수 있도록 연간 인식제고 활동 및 교육훈련 계획을 수립·운영하고, 그 결과에 따른 효과성을 평가하여 다음 계획에 반영하여야 한다. | G29: Y | H29: ISMS-P | I29: 정보보호 교육은 수립된 계획에 따라 정보보호관리체계 범위 내 임직원을 대상으로 연 1회 이상 정보보호 교육을 수행하도록 함 - 연간 (개인)정보보호 교육 계획 수립 후 '정보보호위원회'에 보고 하고 있음 - 신규 입사자는 입사시 정보보호 교육을 진행하고 있으며, 외부직원은 투입된 인력에 대해 교육을 실시함 - 정보보호 온라인 교육을 연 1회 전 임직원 대상으로 진행하고 있음 - 정보보호 교육 시행 후 교육 참가확인서를 기재하도록 하고 있으며, 교육 내용의 적정성과 효과성을 평가하기 위한 교육 설문서를 수령하여 차기 교육에 반영할 수 있도록 함 | J29: 「정보보안관리지침」 제24조(정보보호 교육 계획 수립) 제25조(정보보호 교육 수행) 제26조(정보보호 교육 결과 보고) 「개인정보보호관리지침」 제35조(개인정보 분실, 유출 및 오남용 등 보고) ②항 제43조(개인정보 교육 수립 및 실시) | K29: - 제1회 정보보호위원회 : 안건3 - (개인)정보보호 연간 계획 - 온라인 (개인)정보보호 교육 - 신입직원 (개인)정보보호 교육 - 외주인력 (개인)정보보호 교육
D30: 2.2.5 | E30: 퇴직 및 직무변경 관리 | F30: 퇴직 및 직무변경 시 인사·정보보호·개인정보보호·IT 등 관련 부서별 이행하여야 할 자산반납, 계정 및 접근권한 회수·조정, 결과확인 등의 절차를 수립·관리하여야 한다. | G30: Y | H30: ISMS-P | I30: 부서이동 및 직무변경, 퇴직 시 관리절차를 수립하여 운영함 - 그룹웨어 인사 게시판을 통해 인사변동 정보를 공유함 - 퇴직자 발생 시 자산반납내역서와 보안체크리스트를 통해 자산 반납, 시스템 접근권한 삭제 등의 조치를 수행하고 있음 | J30: 「정보보안관리지침」 제27조(퇴직 시 보안관리) ④항 제29조(외주인력 계약 종료 시 보안) ①항 「개인정보보호관리지침」 제33조(안전조치의무) ①항 | K30: - 사내보안일일업무보고 : 퇴사자/부서 이동자 계정 및 권한 관리 - DS 사내 월간 보안점검 결과 : 2.퇴사자 보안 점검 - 퇴사(예정)직원 통보서 : 점검자 점검 결과
D31: 2.2.6 | E31: 보안 위반 시 조치 | F31: 임직원 및 관련 외부자가 법령, 규제 및 내부정책을 위반한 경우 이에 따른 조치 절차를 수립·이행하여야 한다. | G31: Y | H31: ISMS-P | I31: 정보보호에 대한 책무를 충실히 이행하지 않고 조직의 중요한 정보를 훼손하거나 누출한 경우 징계 기준에 따라 처벌절차를 수립하고 있음 -징계 대상이 되는 위반사항을 발견할 경우 인사위원회에 안건을 상정할 수 있음 - ADS를 통해 인가되지 않은 행위 등 정책 위반 시 소명을 발생시키며, 각 부서 담당자 승인 하에 제출하도록 프로세스가 구성되어 있음 | J31: 「정보보안관리지침」 제118조(징계 기준 수립 목적 및 절차 제119조(징계 구분 및 기준) 「상벌규정」 제14조(징계 대상) 제15조(징계구분 및 기준) | K31: - 상벌규정 - 내부통제이상징후탐지시스템(ADS)업무절차정의서
B32: 2.3. | C32: 외부자 보안 | D32: 2.3.1 | E32: 외부자 현황 관리 | F32: 업무의 일부(개인정보취급, 정보보호, 정보시스템 운영 또는 개발 등)를 외부에 위탁하거나 외부의 시설 또는 서비스(집적정보통신시설, 클라우드 서비스, 애플리케이션 서비스 등)를 이용하는 경우 그 현황을 식별하고 법적 요구사항 및 외부 조직·서비스로부터 발생되는 위험을 파악하여 적절한 보호대책을 마련하여야 한다. | G32: Y | H32: ISMS-P | I32: 개인정보 처리업무 보안관리 약정서에 근거하여, 수행 목적 외 개인정보 처리 금지 등에 관한 사항을 명시하고 있음 - 위탁 계약 체결 및 종료 시 보안점검(보호대책, 파기 등)을 실시하고 있음 - 위탁 계약 중 반기 1회 자체 보안진단을 회신 받아 검토하며, 연 1회 현장점검을 실시하고 있음 | J32: 「개인정보보관리지침」 제26조(업무위탁에 따른 개인정보의 처리제한) 제27조(수탁자의 선정 시 고려사항) 제28조(위수탁 종료 시 관리) | K32: - 상/하반기 개인정보 수탁사 보안점검 결과 보고 - 수탁사 개인정보보호교육 내역 : [2023년 하반기 개인정보 수탁사 보안점검 결과 보고] 5. 개인정보보호 교육 결과 - 보안관리 약정서(위탁업체 계약용) - 외주인력 현황 관리
D33: 2.3.2 | E33: 외부자 계약 시 보안 | F33: 외부 서비스를 이용하거나 외부자에게 업무를 위탁하는 경우 이에 따른 정보보호 및 개인정보보호 요구사항을 식별하고, 관련 내용을 계약서 또는 협정서 등에 명시하여야 한다. | G33: Y | H33: ISMS-P | I33: 외주업체와 계약 시 보안요구사항을 분석하여 계약서에 개인/정보보호 준수에 대한 항목을 반영함 - 신한금융그룹표준계약서를 통하여 계약하고 있으며, 외부 서비스 이용 및 업무 위탁 시 정보보호 요구사항을 식별하고 있음 | J33: 「정보보안관리지침」 제21조(외주인력 관리방안) ①항, ②항 제89조(외주개발 계약) 제90조(외주개발 통제) | K33: - 계약서 - 보안진단_계약서 - 개인정보 처리업무 약정서 및 사전보안진단
D34: 2.3.3 | E34: 외부자 보안 이행 관리 | F34: 계약서, 협정서, 내부정책에 명시된 정보보호 및 개인정보보호 요구사항에 따라 외부자의 보호대책 이행 여부를 주기적인 점검 또는 감사 등 관리·감독하여야 한다. | G34: Y | H34: ISMS-P | I34: 외주 인력이 준수할 항목을 관리·감독하고, 정보보호의날에 외부인력을 포함하여 점검을 진행하고 있음 - 외부인력에 대한 점검을 수행한 후 미흡한 부분에 대해 통지하여 조치하도록 하고 있음 - 개인정보 처리업무의 제3자에게 재위탁 시 관련 보안 점검 현황 등을 검토하고 있음 | J34: 「정보보안관리지침」 제21조(외주인력 관리방안) 「개인정보보호관리지침」 제16조(개인정보를 제공받은 자의 이용·제공 제한) | K34: - 외주인력 점검체크리스트 - 외주인력 정보보호 교육자료 : 교육 플랫폼 활용(당사 앱) - 외주인력보안관리절차서 - DS 사내 월간 보안점검 결과 : 3. 외주 인력 보안 점검
D35: 2.3.4 | E35: 외부자 계약 변경 및 만료 시 보안 | F35: 외부자 계약만료, 업무종료, 담당자 변경 시에는 제공한 정보자산 반납, 정보시스템 접근계정 삭제, 중요정보 파기, 업무 수행 중 취득정보의 비밀유지 확약서 징구 등의 보호대책을 이행하여야 한다. | G35: Y | H35: ISMS-P | I35: 외부자와의 계약만료 및 업무 종료 시 정보보호점검표에 따라 점검이 이뤄지며, 자산반납 및 업무 중 사용하였던 모든 접근계정을 삭제하였는가를 확인함 - 외부자와의 계약만료, 업무종료, 담당자 변경에 따른 보안관리는 외부인력보안지침의 절차에 따라 정보보호점검을 수행함 - 수탁자에게 제공된 개인정보가 업무 목적 달성 후 즉시 파기하며, 파기를 확인하고 있음 | J35: 「정보보호관리지침」 제28조(외주인력 계약 종료 시 보안) 「개인정보보호관리지침」 제28조(위수탁 종료시 관리) | K35: - 외부 정보보호점검표(종료 시) - 보안서약서 - DS 사내 월간 보안점검 결과 : 3. 외주 인력 보안 점검
B36: 2.4. | C36: 물리 보안 | D36: 2.4.1 | E36: 보호구역 지정 | F36: 물리적·환경적 위협으로부터 개인정보 및 중요정보, 문서, 저장매체, 주요 설비 및 시스템 등을 보호하기 위하여 통제구역·제한구역·접견구역 등 물리적 보호구역을 지정하고 각 구역별 보호대책을 수립·이행하여야 한다. | G36: Y | H36: ISMS-P | I36: 보호구역은 통제구역, 제한구역, 접견구역으로 구분하였으며, IDC의 출입은 업무담당자에게 사전 출입신청 요청 후 방문확인 및 출입카드를 교환하여 출입함 -신한금융그룹전산센터에는 24시간 상주하는 경비원이 배치되어 있으며, 모니터링을 위한 CCTV 설비 및 출입카드에 의한 출입통제시스템을 적용하여 운영함 | J36: 「정보보안관리지침」 제29조 (보호구역 설정) ①항, ②항 제30조(보호구역 출입 통제) | K36: - 통제구역출입통제절차서
D37: 2.4.2 | E37: 출입통제 | F37: 보호구역은 인가된 사람만이 출입하도록 통제하고 책임추적성을 확보할 수 있도록 출입 및 접근 이력을 주기적으로 검토하여야 한다. | G37: Y | H37: ISMS-P | I37: 보호구역에 인가된 내부자는 출입통제시스템에 등록되어 출입이 허가됨 -신한금융그룹전산센터 출입이 필요한 경우 외부자는 출입등록시스템 사전등록 및 관리자 승인이 있어야 하며, 출입 시 신분증 확인 및 스마트폰 보안스티커를 부착하고 담당자와 동행하여 출입하도록 되어 있음 -신한금융그룹전산센터에서 매일 출입 통제 현황에 대해 확인하고 목록을 보관하고 있음 - 본사는 층별 통신실에 대해 상시 출입자 등록/관리를 수행하고 있으며, 외부직원의 출입이 필요한 경우 담당자 동행하여 출입하도록 하고 있음 | J37: 「정보보안관리지침」 제29조(보호구역 설정) ①항, ②항 제30조(보호구역 출입 통제) | K37: - IDC 전산실 출입 절차 - 백년관 출입권한 신청/삭제 - 백년관 통신실 출입관리대장 - 정보자산 반/출입 신청서 - 출입카드 발급 신청서 - 월간운영보고서_직원만족팀
D38: 2.4.3 | E38: 정보시스템 보호 | F38: 정보시스템은 환경적 위협과 유해요소, 비인가 접근 가능성을 감소시킬 수 있도록 중요도와 특성을 고려하여 배치하고, 통신 및 전력 케이블이 손상을 입지 않도록 보호하여야 한다. | G38: Y | H38: ISMS-P | I38: 정보시스템은 신한금융그룹전산센터에 배치하고 있음 - 전산실 내 렉실장도가 배치되어 있으며, 전력 및 통신케이블은 외부에 노출되지 않도록 이중바닥에 설치되어 있으며, 외부에 노출된 케이블은 케이지로 감싸고 있음 | J38: 「정보보안관리지침」 제34조(전산실 보호를 위한 운용관리 사항) ①항, ②항 | K38: - 실사(죽전센터) > IDC 내부 사진 촬영 불가
D39: 2.4.4 | E39: 보호설비 운영 | F39: 보호구역에 위치한 정보시스템의 중요도 및 특성에 따라 온도·습도 조절, 화재감지, 소화설비, 누수감지, UPS, 비상발전기, 이중전원선 등의 보호설비를 갖추고 운영절차를 수립·운영하여야 한다. | G39: Y | H39: ISMS-P | I39: 신한금융그룹전산센터는 인재 및 자연재해 등에 대비한 설비를 갖추고 운영하고 있음 ①소화기 및 소화설비(스프링쿨러, 하론가스) ②피뢰설비 ③감시제어시스템(FMS) ④자가발전기(3일 보장) ⑤전력선 복수회선 ⑥무정전전원장치(UPS) 30분 이상 공급 가능 ⑦누수감지기 ⑧항온항습기 | J39: 「정보보안관리지침」 제34조(전산실 보호를 위한 운용관리 사항) ①항, ②항 | K39: - 실사(죽전센터) > IDC 내부 사진 촬영 불가
D40: 2.4.5 | E40: 보호구역 내 작업 | F40: 보호구역 내에서의 비인가행위 및 권한 오·남용 등을 방지하기 위한 작업 절차를 수립·이행하고, 작업 기록을 주기적으로 검토하여야 한다. | G40: Y | H40: ISMS-P | I40: 신한금융그룹전산센터 출입 시 출입등록을 사전에 신청하고 신분증 확인 및 담당자 동행하에 출입 가능하며, 전산실에 출입이 필요한 경우 전산실 출입 신청 및 출입권한이 부여된 담당자가 동행하여 출입 | J40: 「정보보안관리지침」 제32조(통제구역 내 작업) ①항, ②항, ④항 | K40: - IDC 전산실 작업
D41: 2.4.6 | E41: 반출입 기기 통제 | F41: 보호구역 내 정보시스템, 모바일 기기, 저장매체 등에 대한 반출입 통제절차를 수립·이행하고 주기적으로 검토하여야 한다. | G41: Y | H41: ISMS-P | I41: 정보시스템, 모바일기기, 저장매체 등을 반출입해야 할 경우 자산반출입 신청서를 작성하여 관리하고 있음 | J41: 「정보보안관리지침」 제32조(통제구역 내 작업) ③항 제33조(통제구역 내 모바일기기 반출·입) | K41: - 정보자산 반출입 신청서 : 본사 및 IDC
D42: 2.4.7 | E42: 업무환경 보안 | F42: 공용으로 사용하는 사무용 기기(문서고, 공용 PC, 복합기, 파일서버 등) 및 개인 업무환경(업무용 PC, 책상 등)을 통해 개인정보 및 중요정보가 비인가자에게 노출 또는 유출되지 않도록 클린데스크, 정기점검 등 업무환경 보호대책을 수립·이행하여야 한다. | G42: Y | H42: ISMS-P | I42: 매월 정보보호의날을 통하여 사무용 기기 및 개인 업무 환경에 대한 점검을 수행하고 있음 - 매월 정보보호의날을 통하여 공용공간, 업무용 PC 시건장치, 문서방치, 중요정보(패스워드) 방치 여부 등을 점검하고 있음 - 개인정보 파일 관리여부를 EDLP, ADS를 통해 모니터링 하며, 위반사항에 대해서 소명요구하고 있음 | J42: 「정보보안관리지침」 제18조(정보보호의 날 운영) 제35조(개인업무 환경 보안) 제36조(공용업무 환경 보안) 「개인정보보호관리지침」 제33조(안전조치의무) | K42: - 월간 보안 활동 보고 - 정보보호의 날 시행 안내
...
